Workbook

Sheet 02-03-01
A1: Id | B1: Code | C1: Name | D1: Installing | E1: Commissioning | F1: Decommissioning | G1: Status | H1: Structure | I1: SQL Insert Request
A2: F_00 | B2: F_01 | C2: F_02 | D2: F_03 | E2: F_04 | F2: F_05 | G2: F_06 | H2: F_07 | I2: INSERT INTO T_02_03_01 (F_00, F_01, F_02, F_03, F_04, F_05, F_06, F_07) VALUES
A3: 1 | B3: ONET-DD | C3: Terminal d\'Exportation Terrestre Deb Deb | D3: 38426 | E3: 39406 | F3: NULL | G3: 1 | H3: 10 | I3: =CONCATENATE("(",A3,",'",B3,"','",C3,"','",TEXT(D3,"aaaa-mm-jj"),"','",TEXT(E3,"aaaa-mm-jj"),"',",F3,",",G3,",",H3,"),") -> (1,'ONET-DD','Terminal d\'Exportation Terrestre Deb Deb','2005-03-15','2007-11-20',NULL,1,10),
A4: 2 | B4: ONET-OSS | C4: Terminal d\'Exportation Terrestre Oued Saf Saf | D4: 39609 | E4: 40436 | F4: NULL | G4: 1 | H4: 10 | I4: =CONCATENATE("(",A4,",'",B4,"','",C4,"','",TEXT(D4,"aaaa-mm-jj"),"','",TEXT(E4,"aaaa-mm-jj"),"',",F4,",",G4,",",H4,"),") -> (2,'ONET-OSS','Terminal d\'Exportation Terrestre Oued Saf Saf','Tuesday-06-jj','Wednesday-09-jj',NULL,1,10),
A5: 3 | B5: ONET-BS | C5: Terminal d\'Exportation Terrestre Beni Saf | D5: 38827 | E5: 39792 | F5: NULL | G5: 1 | H5: 10 | I5: =CONCATENATE("(",A5,",'",B5,"','",C5,"','",TEXT(D5,"aaaa-mm-jj"),"','",TEXT(E5,"aaaa-mm-jj"),"',",F5,",",G5,",",H5,"),") -> (3,'ONET-BS','Terminal d\'Exportation Terrestre Beni Saf','Thursday-04-jj','Wednesday-12-jj',NULL,1,10),
A6: 4 | B6: ONET-KL | C6: Terminal d\'Exportation Terrestre El Kala | D6: 40909 | E6: 40909 | F6: NULL | G6: 1 | H6: 10 | I6: =CONCATENATE("(",A6,",'",B6,"','",C6,"','",TEXT(D6,"aaaa-mm-jj"),"','",TEXT(E6,"aaaa-mm-jj"),"',",F6,",",G6,",",H6,"),") -> (4,'ONET-KL','Terminal d\'Exportation Terrestre El Kala','Sunday-01-jj','Sunday-01-jj',NULL,1,10),
A7: 5 | B7: DZAZW | C7: Terminal d\'Exportation Maritime Arzew | D7: 28505 | E7: 29757 | F7: NULL | G7: 1 | H7: 10 | I7: =CONCATENATE("(",A7,",'",B7,"','",C7,"','",TEXT(D7,"aaaa-mm-jj"),"','",TEXT(E7,"aaaa-mm-jj"),"',",F7,",",G7,",",H7,"),") -> (5,'DZAZW','Terminal d\'Exportation Maritime Arzew','1978-01-15','1981-06-20',NULL,1,10),
A8: 6 | B8: DZSKI | C8: Terminal d\'Exportation Maritime Skikda | D8: 26368 | E8: 27662 | F8: NULL | G8: 1 | H8: 10 | I8: =CONCATENATE("(",A8,",'",B8,"','",C8,"','",TEXT(D8,"aaaa-mm-jj"),"','",TEXT(E8,"aaaa-mm-jj"),"',",F8,",",G8,",",H8,"),") -> (6,'DZSKI','Terminal d\'Exportation Maritime Skikda','1972-03-10','1975-09-25',NULL,1,10),
A9: 7 | B9: DZBJA | C9: Terminal d\'Exportation Maritime Bejaia | D9: 35927 | E9: 36968 | F9: NULL | G9: 1 | H9: 10 | I9: =CONCATENATE("(",A9,",'",B9,"','",C9,"','",TEXT(D9,"aaaa-mm-jj"),"','",TEXT(E9,"aaaa-mm-jj"),"',",F9,",",G9,",",H9,"),") -> (7,'DZBJA','Terminal d\'Exportation Maritime Bejaia','1998-05-12','2001-03-18',NULL,1,10),
A10: 8 | B10: CDHL | C10: Terminal de Distribution CDHL | D10: 37660 | E10: 38640 | F10: NULL | G10: 1 | H10: 10 | I10: =CONCATENATE("(",A10,",'",B10,"','",C10,"','",TEXT(D10,"aaaa-mm-jj"),"','",TEXT(E10,"aaaa-mm-jj"),"',",F10,",",G10,",",H10,"),") -> (8,'CDHL','Terminal de Distribution CDHL','2003-02-08','2005-10-15',NULL,1,10),
A11: 9 | B11: CNDG | C11: Terminal de Distribution CNDG | D11: 38188 | E11: 39051 | F11: NULL | G11: 1 | H11: 10 | I11: =CONCATENATE("(",A11,",'",B11,"','",C11,"','",TEXT(D11,"aaaa-mm-jj"),"','",TEXT(E11,"aaaa-mm-jj"),"',",F11,",",G11,",",H11,"),") -> (9,'CNDG','Terminal de Distribution CNDG','2004-07-20','2006-11-30',NULL,1,10),
A12: 10 | B12: DT-MED | C12: Terminal de Distribution Medjedel | D12: 39340 | E12: 40047 | F12: NULL | G12: 1 | H12: 10 | I12: =CONCATENATE("(",A12,",'",B12,"','",C12,"','",TEXT(D12,"aaaa-mm-jj"),"','",TEXT(E12,"aaaa-mm-jj"),"',",F12,",",G12,",",H12,"),") -> (10,'DT-MED','Terminal de Distribution Medjedel','Saturday-09-jj','Saturday-08-jj',NULL,1,10),
A13: 11 | B13: DT-MSL | C13: Terminal de Distribution M\'Sila | D13: 39556 | E13: 40371 | F13: NULL | G13: 1 | H13: 10 | I13: =CONCATENATE("(",A13,",'",B13,"','",C13,"','",TEXT(D13,"aaaa-mm-jj"),"','",TEXT(E13,"aaaa-mm-jj"),"',",F13,",",G13,",",H13,"),") -> (11,'DT-MSL','Terminal de Distribution M\'Sila','2008-04-18','2010-07-12',NULL,1,10),
A14: 12 | B14: DT-DJM | C14: Terminal de Distribution SP1 Bis Djamaa | D14: 40122 | E14: 40719 | F14: NULL | G14: 1 | H14: 10 | I14: =CONCATENATE("(",A14,",'",B14,"','",C14,"','",TEXT(D14,"aaaa-mm-jj"),"','",TEXT(E14,"aaaa-mm-jj"),"',",F14,",",G14,",",H14,"),") -> (12,'DT-DJM','Terminal de Distribution SP1 Bis Djamaa','2009-11-05','2011-06-25',NULL,1,10),
... A17: 15 | B17: TT-BNM | C17: Terminal de Transfert Beni Mensour | D17: 40683 | E17: 41593 | F17: NULL | G17: 1 | H17: 10 | I17: =CONCATENATE("(",A17,",'",B17,"','",C17,"','",TEXT(D17,"aaaa-mm-jj"),"','",TEXT(E17,"aaaa-mm-jj"),"',",F17,",",G17,",",H17,"),") -> (15,'TT-BNM','Terminal de Transfert Beni Mensour','2011-05-20','2013-11-15',NULL,1,10),
B18: TT-HRM | C18: Terminal de Transfert Hassi R'Mel
A19: 16 | B19: TT-HMD | C19: Terminal de Transfert Hassi Messaoud | D19: 37478 | E19: 38341 | F19: NULL | G19: 1 | H19: 10 | I19: =CONCATENATE("(",A19,",'",B19,"','",C19,"','",TEXT(D19,"aaaa-mm-jj"),"','",TEXT(E19,"aaaa-mm-jj"),"',",F19,",",G19,",",H19,"),") -> (16,'TT-HMD','Terminal de Transfert Hassi Messaoud','Saturday-08-jj','Monday-12-jj',NULL,1,10),
A20: 17 | B20: PT-MSD | C20: Terminal de Transfert Mesdar | D20: 38518 | E20: 39385 | F20: NULL | G20: 1 | H20: 10 | I20: =CONCATENATE("(",A20,",'",B20,"','",C20,"','",TEXT(D20,"aaaa-mm-jj"),"','",TEXT(E20,"aaaa-mm-jj"),"',",F20,",",G20,",",H20,"),") -> (17,'PT-MSD','Terminal de Transfert Mesdar','Wednesday-06-jj','Tuesday-10-jj',NULL,1,10),
A21: 18 | B21: TT-OHT | C21: Terminal de Transfert Ohanet | D21: 38982 | E21: 39678 | F21: NULL | G21: 1 | H21: 10 | I21: =CONCATENATE("(",A21,",'",B21,"','",C21,"','",TEXT(D21,"aaaa-mm-jj"),"','",TEXT(E21,"aaaa-mm-jj"),"',",F21,",",G21,",",H21,"),") -> (18,'TT-OHT','Terminal de Transfert Ohanet','Friday-09-jj','Monday-08-jj',NULL,1,10),
A22: 19 | B22: TT-137 | C22: Terminal de Transfert PC1/PK137 | D22: 39421 | E22: 40014 | F22: NULL | G22: 1 | H22: 10 | I22: =CONCATENATE("(",A22,",'",B22,"','",C22,"','",TEXT(D22,"aaaa-mm-jj"),"','",TEXT(E22,"aaaa-mm-jj"),"',",F22,",",G22,",",H22,"),") -> (19,'TT-137','Terminal de Transfert PC1/PK137','2007-12-05','2009-07-20',NULL,1,10),
A23: 20 | B23: TT-RDN | C23: Terminal de Transfert Rhoude Nouss | D23: 39525 | E23: 40323 | F23: NULL | G23: 1 | H23: 10 | I23: =CONCATENATE("(",A23,",'",B23,"','",C23,"','",TEXT(D23,"aaaa-mm-jj"),"','",TEXT(E23,"aaaa-mm-jj"),"',",F23,",",G23,",",H23,"),") -> (20,'TT-RDN','Terminal de Transfert Rhoude Nouss','Tuesday-03-jj','Tuesday-05-jj',NULL,1,10),
A24: 21 | B24: PT-ALG | C24: Terminal de Pipeline Alger | D24: 34709 | E24: 35688 | F24: NULL | G24: 1 | H24: 10 | I24: =CONCATENATE("(",A24,",'",B24,"','",C24,"','",TEXT(D24,"aaaa-mm-jj"),"','",TEXT(E24,"aaaa-mm-jj"),"',",F24,",",G24,",",H24,"),") -> (21,'PT-ALG','Terminal de Pipeline Alger','1995-01-10','1997-09-15',NULL,1,10),
A25: 22 | B25: PT-ALR | C25: Terminal de Pipeline Alrar | D25: 35907 | E25: 36860 | F25: NULL | G25: 1 | H25: 10 | I25: =CONCATENATE("(",A25,",'",B25,"','",C25,"','",TEXT(D25,"aaaa-mm-jj"),"','",TEXT(E25,"aaaa-mm-jj"),"',",F25,",",G25,",",H25,"),") -> (22,'PT-ALR','Terminal de Pipeline Alrar','Wednesday-04-jj','Thursday-11-jj',NULL,1,10),
A26: 23 | B26: PT-ARZ | C26: Terminal de Pipeline Arzew | D26: 29387 | E26: 30375 | F26: NULL | G26: 1 | H26: 10 | I26: =CONCATENATE("(",A26,",'",B26,"','",C26,"','",TEXT(D26,"aaaa-mm-jj"),"','",TEXT(E26,"aaaa-mm-jj"),"',",F26,",",G26,",",H26,"),") -> (23,'PT-ARZ','Terminal de Pipeline Arzew','Sunday-06-jj','Monday-02-jj',NULL,1,10),
B27: PT-AEB | C27: Terminal de Pipeline Ain El Bya
B28: PT-BTA | C28: Terminal de Pipeline Bethioua
A29: 24 | B29: PT-BJA | C29: Terminal de Pipeline Bejaia | D29: 35662 | E29: 36504 | F29: NULL | G29: 1 | H29: 10 | I29: =CONCATENATE("(",A29,",'",B29,"','",C29,"','",TEXT(D29,"aaaa-mm-jj"),"','",TEXT(E29,"aaaa-mm-jj"),"',",F29,",",G29,",",H29,"),") -> (24,'PT-BJA','Terminal de Pipeline Bejaia','Wednesday-08-jj','Friday-12-jj',NULL,1,10),
A30: 25 | B30: PT-BRN | C30: Terminal de Pipeline Bir Rebaa North | D30: 36965 | E30: 37827 | F30: NULL | G30: 1 | H30: 10 | I30: =CONCATENATE("(",A30,",'",B30,"','",C30,"','",TEXT(D30,"aaaa-mm-jj"),"','",TEXT(E30,"aaaa-mm-jj"),"',",F30,",",G30,",",H30,"),") -> (25,'PT-BRN','Terminal de Pipeline Bir Rebaa North','2001-03-15','2003-07-25',NULL,1,10),
A31: 26 | B31: PT-BMN | C31: Terminal de Pipeline Bordj Menaiel | D31: 35377 | E31: 36029 | F31: NULL | G31: 1 | H31: 10 | I31: =CONCATENATE("(",A31,",'",B31,"','",C31,"','",TEXT(D31,"aaaa-mm-jj"),"','",TEXT(E31,"aaaa-mm-jj"),"',",F31,",",G31,",",H31,"),") -> (26,'PT-BMN','Terminal de Pipeline Bordj Menaiel','Friday-11-jj','Saturday-08-jj',NULL,1,10),
A32: 27 | B32: PT-BRM | C32: Terminal de Pipeline El Borma | D32: 36658 | E32: 37547 | F32: NULL | G32: 1 | H32: 10 | I32: =CONCATENATE("(",A32,",'",B32,"','",C32,"','",TEXT(D32,"aaaa-mm-jj"),"','",TEXT(E32,"aaaa-mm-jj"),"',",F32,",",G32,",",H32,"),") -> (27,'PT-BRM','Terminal de Pipeline El Borma','Friday-05-jj','Friday-10-jj',NULL,1,10),
A33: 28 | B33: PT-GST | C33: Terminal de Pipeline Gassi Touil | D33: 37869 | E33: 38523 | F33: NULL | G33: 1 | H33: 10 | I33: =CONCATENATE("(",A33,",'",B33,"','",C33,"','",TEXT(D33,"aaaa-mm-jj"),"','",TEXT(E33,"aaaa-mm-jj"),"',",F33,",",G33,",",H33,"),") -> (28,'PT-GST','Terminal de Pipeline Gassi Touil','Friday-09-jj','Monday-06-jj',NULL,1,10),
A34: 29 | B34: PT-HBK | C34: Terminal de Pipeline Hassi Berkine | D34: 38035 | E34: 38837 | F34: NULL | G34: 1 | H34: 10 | I34: =CONCATENATE("(",A34,",'",B34,"','",C34,"','",TEXT(D34,"aaaa-mm-jj"),"','",TEXT(E34,"aaaa-mm-jj"),"',",F34,",",G34,",",H34,"),") -> (29,'PT-HBK','Terminal de Pipeline Hassi Berkine','Wednesday-02-jj','Sunday-04-jj',NULL,1,10),
A35: 30 | B35: PT-HTJ | C35: Terminal de Pipeline Hassi tedjirane | D35: 38555 | E35: 39340 | F35: NULL | G35: 1 | H35: 10 | I35: =CONCATENATE("(",A35,",'",B35,"','",C35,"','",TEXT(D35,"aaaa-mm-jj"),"','",TEXT(E35,"aaaa-mm-jj"),"',",F35,",",G35,",",H35,"),") -> (30,'PT-HTJ','Terminal de Pipeline Hassi tedjirane','2005-07-22','2007-09-15',NULL,1,10),
A36: 31 | B36: PT-NMS | C36: Terminal de Pipeline In Amenas | D36: 37537 | E36: 38224 | F36: NULL | G36: 1 | H36: 10 | I36: =CONCATENATE("(",A36,",'",B36,"','",C36,"','",TEXT(D36,"aaaa-mm-jj"),"','",TEXT(E36,"aaaa-mm-jj"),"',",F36,",",G36,",",H36,"),") -> (31,'PT-NMS','Terminal de Pipeline In Amenas','Tuesday-10-jj','Wednesday-08-jj',NULL,1,10),
A37: 32 | B37: PT-NSL | C37: Terminal de Pipeline In Salah | D37: 39066 | E37: 39772 | F37: NULL | G37: 1 | H37: 10 | I37: =CONCATENATE("(",A37,",'",B37,"','",C37,"','",TEXT(D37,"aaaa-mm-jj"),"','",TEXT(E37,"aaaa-mm-jj"),"',",F37,",",G37,",",H37,"),") -> (32,'PT-NSL','Terminal de Pipeline In Salah','2006-12-15','2008-11-20',NULL,1,10),
A38: 33 | B38: PT-ISR | C38: Terminal de Pipeline Isser | D38: 35509 | E38: 36290 | F38: NULL | G38: 1 | H38: 10 | I38: =CONCATENATE("(",A38,",'",B38,"','",C38,"','",TEXT(D38,"aaaa-mm-jj"),"','",TEXT(E38,"aaaa-mm-jj"),"',",F38,",",G38,",",H38,"),") -> (33,'PT-ISR','Terminal de Pipeline Isser','1997-03-20','1999-05-10',NULL,1,10),
A39: 34 | B39: PT-RGN | C39: Terminal de Pipeline Reggane | D39: 40341 | E39: 41212 | F39: NULL | G39: 1 | H39: 10 | I39: =CONCATENATE("(",A39,",'",B39,"','",C39,"','",TEXT(D39,"aaaa-mm-jj"),"','",TEXT(E39,"aaaa-mm-jj"),"',",F39,",",G39,",",H39,"),") -> (34,'PT-RGN','Terminal de Pipeline Reggane','Saturday-06-jj','Tuesday-10-jj',NULL,1,10),
A40: 35 | B40: PT-RBL | C40: Terminal de Pipeline Rhoude El Baguel | D40: 37152 | E40: 37977 | F40: NULL | G40: 1 | H40: 10 | I40: =CONCATENATE("(",A40,",'",B40,"','",C40,"','",TEXT(D40,"aaaa-mm-jj"),"','",TEXT(E40,"aaaa-mm-jj"),"',",F40,",",G40,",",H40,"),") -> (35,'PT-RBL','Terminal de Pipeline Rhoude El Baguel','Tuesday-09-jj','Monday-12-jj',NULL,1,10),
A41: 36 | B41: PT-SKD | C41: Terminal de Pipeline Skikda | D41: 27494 | E41: 28505 | F41: NULL | G41: 1 | H41: 10 | I41: =CONCATENATE("(",A41,",'",B41,"','",C41,"','",TEXT(D41,"aaaa-mm-jj"),"','",TEXT(E41,"aaaa-mm-jj"),"',",F41,",",G41,",",H41,"),") -> (36,'PT-SKD','Terminal de Pipeline Skikda','Thursday-04-jj','Sunday-01-jj',NULL,1,10),
B42: PT-SC4SGR | C42: Terminal de Pipeline Sougueur | D42: 43101 | E42: 43101 | F42: NULL | G42: 1 | H42: 10 | I42: =CONCATENATE("(",A42,",'",B42,"','",C42,"','",TEXT(D42,"aaaa-mm-jj"),"','",TEXT(E42,"aaaa-mm-jj"),"',",F42,",",G42,",",H42,"),") -> (,'PT-SC4SGR','Terminal de Pipeline Sougueur','2018-01-01','2018-01-01',NULL,1,10),
...

Sheet Stations
B1: SC | E1: SP | H1: PRS
B2: Working | C2: Stoped | D2: Decomissioned | E2: Working | F2: Stoped | G2: Decomissioned | H2: Working | I2: Stoped | J2: Decomissioned
A3: GZ0 | B3: 0 | C3: 0 | D3: 4 | H3: 0 | I3: 0 | J3: 0
A4: GZ1/2/3 | B4: 15 | C4: 0 | D4: 0 | H4: 0 | I4: 0 | J4: 0
A5: GZ4 | B5: 0 | C5: 0 | D5: 0 | H5: 0 | I5: 0 | J5: 0
A6: GK1/2 | B6: 5 | C6: 0 | D6: 0 | H6: 0 | I6: 0 | J6: 0
A7: GK3 | B7: 0 | C7: 0 | D7: 0 | H7: 0 | I7: 0 | J7: 0
A8: GG1 | B8: 1 | C8: 0 | D8: 0 | H8: 0 | I8: 0 | J8: 0
A9: GR1/2/4/6 | B9: 6 | C9: 0 | D9: 1 | H9: 0 | I9: 0 | J9: 0
A10: GR5/7 | B10: 2 | C10: 0 | D10: 0 | H10: 0 | I10: 0 | J10: 0
A11: GPDF | B11: 1 | C11: 0 | D11: 0 | H11: 0 | I11: 0 | J11: 0
A12: GO1/2/3 | B12: 1 | C12: 0 | D12: 0 | H12: 0 | I12: 0 | J12: 0
A13: OZ1/2 | E13: 6 | F13: 0 | G13: 6 | H13: 1 | I13: 0 | J13: 1
A14: OK1 | E14: 5 | F14: 0 | G14: 0 | H14: 0 | I14: 0 | J14: 0
A15: OB1/OG1 | E15: 5 | F15: 0 | G15: 9 | H15: 0 | I15: 0 | J15: 0
A16: OH1 | E16: 0 | F16: 3 | G16: 0 | H16: 0 | I16: 0 | J16: 0
A17: OD1/3/OH2 | E17: 2 | F17: 0 | G17: 0 | H17: 0 | I17: 0 | J17: 0
A18: OH3/OH4 | E18: 1 | F18: 1 | G18: 0 | H18: 0 | I18: 0 | J18: 0
A19: OT1 | E19: 2 | F19: 0 | G19: 0 | H19: 0 | I19: 0 | J19: 0
A20: NZ1 | E20: 3 | F20: 0 | G20: 0 | H20: 1 | I20: 0 | J20: 0
A21: NK1 | E21: 2 | F21: 0 | G21: 0 | H21: 0 | I21: 0 | J21: 0
A22: NH2 | E22: 0 | F22: 0 | G22: 0 | H22: 0 | I22: 0 | J22: 0
A23: LZ1/LZ2 | E23: 3 | F23: 0 | G23: 3 | H23: 2 | I23: 0 | J23: 1
A24: LR1/DLR1/ELR1 | E24: 3 | F24: 0 | G24: 3 | H24: 0 | I24: 0 | J24: 0
B25: =SUM(B3:B24) -> 31 | C25: =SUM(C3:C24) -> 0 | D25: =SUM(D3:D24) -> 5 | E25: =SUM(E3:E24) -> 32 | F25: =SUM(F3:F24) -> 4 | G25: =SUM(G3:G24) -> 21 | H25: =SUM(H3:H24) -> 4 | I25: =SUM(I3:I24) -> 0 | J25: =SUM(J3:J24) -> 2 | K25: =SUM(B25:J25) -> 99
K26: =B25+C25+E25+F25+H25+I25 -> 71
K27: =B25+E25+H25 -> 67

Sheet 02-03-03-TTST
A1: Id | B1: GID | C1: System | D1: SystemId | E1: Code | F1: Name | G1: Installing | H1: Commissioning | I1: Decommissioning | J1: Status | K1: StationType | L1: StTypeId | M1: owner | N1: manager | O1: Pipeline | P1: Coordinate | Q1: Elevation | R1: Distance | S1: Locality | T1: SQL Insert Request
A2: F_00 | E2: F_01 | F2: F_02 | G2: F_03 | H2: F_04 | I2: F_05 | J2: F_06 | M2: F_07 | T2: INSERT INTO T_02_03_01 (F_00, F_01, F_02, F_03, F_04, F_05, F_06, F_07) VALUES
A3: 1 | B3: 1 | C3: OZ1/OZ2 | D3: 1 | E3: =CONCATENATE("PC-",TEXT(A3,"00"),"-",O3) -> PC-01-OZ1 | F3: =CONCATENATE("Poste de Coupure n°",TEXT(A3,"00")," ",O3) -> Poste de Coupure n°01 OZ1 | G3: 24053 | H3: 24053 | I3: NULL | J3: 1 | K3: Block Valve Station | L3: 15 | M3: 16 | O3: OZ1 | P3: 0 / 156 | Q3: =VALUE(RIGHT(P3,LEN(P3)-SEARCH("/",P3))) -> 156 | R3: =VALUE(SUBSTITUTE(LEFT(P3,SEARCH("/",P3)-1),"+",",")) -> 0 | S3: Hassi Messaoud / OUARGLA | T3: =CONCATENATE("(",A3,",'",E3,"','",F3,"','",TEXT(G3,"aaaa-mm-jj"),"','",TEXT(H3,"aaaa-mm-jj"),"',",I3,",",J3,",",M3,"),") -> (1,'PC-01-OZ1','Poste de Coupure n°01 OZ1','Sunday-11-jj','Sunday-11-jj',NULL,1,16),
A4: 1 | B4: 2 | C4: OZ1/OZ2 | D4: 1 | E4: =CONCATENATE("PS-",TEXT(A4,"00"),"-",O4) -> PS-01-OZ1 | F4: =CONCATENATE("Poste de Sectionnement n°",TEXT(A4,"00")," ",O4) -> Poste de Sectionnement n°01 OZ1 | G4: 24053 | H4: 24053 | I4: NULL | J4: 1 | K4: Sectionalizing Station | L4: 16 | M4: 16 | O4: OZ1 | P4: 0+000 / 150 | Q4: =VALUE(RIGHT(P4,LEN(P4)-SEARCH("/",P4))) -> 150 | R4: =VALUE(SUBSTITUTE(LEFT(P4,SEARCH("/",P4)-1),"+",",")) -> 0 | S4: HMD / OUARGLA | T4: =CONCATENATE("(",A4,",'",E4,"','",F4,"','",TEXT(G4,"aaaa-mm-jj"),"','",TEXT(H4,"aaaa-mm-jj"),"',",I4,",",J4,",",M4,"),") -> (1,'PS-01-OZ1','Poste de Sectionnement n°01 OZ1','Sunday-11-jj','Sunday-11-jj',NULL,1,16),
A5: 8 | B5: 3 | C5: OZ1/OZ2 | D5: 1 | E5: SP1-OZ1-D | F5: =CONCATENATE("Station de Pompage ",E5) -> Station de Pompage SP1-OZ1-D | G5: 23743 | H5: 23743 | I5: 37986 | J5: 8 | K5: Pumping Station | L5: 7 | M5: 16 | O5: OZ1 | P5: 0 / 156 | Q5: =VALUE(RIGHT(P5,LEN(P5)-SEARCH("/",P5))) -> 156 | R5: =VALUE(SUBSTITUTE(LEFT(P5,SEARCH("/",P5)-1),"+",",")) -> 0 | S5: Hassi Messaoud / OUARGLA | T5: =CONCATENATE("(",A5,",'",E5,"','",F5,"','",TEXT(G5,"aaaa-mm-jj"),"','",TEXT(H5,"aaaa-mm-jj"),"',",I5,",",J5,",",M5,"),") -> (8,'SP1-OZ1-D','Station de Pompage SP1-OZ1-D','Friday-01-jj','Friday-01-jj',37986,8,16),
A6: 2 | B6: 4 | C6: OZ1/OZ2 | D6: 1 | E6: =CONCATENATE("PS-",TEXT(A6,"00"),"-",O6) -> PS-02-OZ1 | F6: =CONCATENATE("Poste de Sectionnement n°",TEXT(A6,"00")," ",O6) -> Poste de Sectionnement n°02 OZ1 | G6: 24053 | H6: 24053 | I6: NULL | J6: 1 | K6: Sectionalizing Station | L6: 16 | M6: 16 | O6: OZ1 | P6: 44+200 / 150 | Q6: =VALUE(RIGHT(P6,LEN(P6)-SEARCH("/",P6))) -> 150 | R6: =VALUE(SUBSTITUTE(LEFT(P6,SEARCH("/",P6)-1),"+",",")) -> 44.2 | S6: Ain Beida / OUARGLA | T6: =CONCATENATE("(",A6,",'",E6,"','",F6,"','",TEXT(G6,"aaaa-mm-jj"),"','",TEXT(H6,"aaaa-mm-jj"),"',",I6,",",J6,",",M6,"),") -> (2,'PS-02-OZ1','Poste de Sectionnement n°02 OZ1','Sunday-11-jj','Sunday-11-jj',NULL,1,16),
A7: 3 | B7: 5 | C7: OZ1/OZ2 | D7: 1 | E7: =CONCATENATE("PS-",TEXT(A7,"00"),"-",O7) -> PS-03-OZ1 | F7: =CONCATENATE("Poste de Sectionnement n°",TEXT(A7,"00")," ",O7) -> Poste de Sectionnement n°03 OZ1 | G7: 24053 | H7: 24053 | I7: NULL | J7: 1 | K7: Sectionalizing Station | L7: 16 | M7: 16 | O7: OZ1 | P7: 72+000/ 210 | Q7: =VALUE(RIGHT(P7,LEN(P7)-SEARCH("/",P7))) -> 210 | R7: =VALUE(SUBSTITUTE(LEFT(P7,SEARCH("/",P7)-1),"+",",")) -> 72 | S7: OUARGLA | T7: =CONCATENATE("(",A7,",'",E7,"','",F7,"','",TEXT(G7,"aaaa-mm-jj"),"','",TEXT(H7,"aaaa-mm-jj"),"',",I7,",",J7,",",M7,"),") -> (3,'PS-03-OZ1','Poste de Sectionnement n°03 OZ1','Sunday-11-jj','Sunday-11-jj',NULL,1,16),
A8: 2 | B8: 6 | C8: OZ1/OZ2 | D8: 1 | E8: =CONCATENATE("PC-",TEXT(A8,"00"),"-",O8) -> PC-02-OZ1 | F8: =CONCATENATE("Poste de Coupure n°",TEXT(A8,"00")," ",O8) -> Poste de Coupure n°02 OZ1 | G8: 24053 | H8: 24053 | I8: NULL | J8: 1 | K8: Block Valve Station | L8: 15 | M8: 16 | O8: OZ1 | P8: 124+800 / 256 | Q8: =VALUE(RIGHT(P8,LEN(P8)-SEARCH("/",P8))) -> 256 | R8: =VALUE(SUBSTITUTE(LEFT(P8,SEARCH("/",P8)-1),"+",",")) -> 124.8 | S8: Ouargla / OUARGLA | T8: =CONCATENATE("(",A8,",'",E8,"','",F8,"','",TEXT(G8,"aaaa-mm-jj"),"','",TEXT(H8,"aaaa-mm-jj"),"',",I8,",",J8,",",M8,"),") -> (2,'PC-02-OZ1','Poste de Coupure n°02 OZ1','Sunday-11-jj','Sunday-11-jj',NULL,1,16),
A9: 9 | B9: 7 | C9: OZ1/OZ2 | D9: 1 | E9: SP2-OZ1-D | F9: =CONCATENATE("Station de Pompage ",E9) -> Station de Pompage SP2-OZ1-D | G9: 23743 | H9: 23743 | I9: 37986 | J9: 8 | K9: Pumping Station | L9: 7 | M9: 16 | O9: OZ1 | P9: 124+800 / 256 | Q9: =VALUE(RIGHT(P9,LEN(P9)-SEARCH("/",P9))) -> 256 | R9: =VALUE(SUBSTITUTE(LEFT(P9,SEARCH("/",P9)-1),"+",",")) -> 124.8 | S9: Ouargla / OUARGLA | T9: =CONCATENATE("(",A9,",'",E9,"','",F9,"','",TEXT(G9,"aaaa-mm-jj"),"','",TEXT(H9,"aaaa-mm-jj"),"',",I9,",",J9,",",M9,"),") -> (9,'SP2-OZ1-D','Station de Pompage SP2-OZ1-D','Friday-01-jj','Friday-01-jj',37986,8,16),
A10: 4 | B10: 8 | C10: OZ1/OZ2 | D10: 1 | E10: =CONCATENATE("PS-",TEXT(A10,"00"),"-",O10) -> PS-04-OZ1 | F10: =CONCATENATE("Poste de Sectionnement n°",TEXT(A10,"00")," ",O10) -> Poste de Sectionnement n°04 OZ1 | G10: 24053 | H10: 24053 | I10: NULL | J10: 1 | K10: Sectionalizing Station | L10: 16 | M10: 16 | O10: OZ1 | P10: 145+473 / 295 | Q10: =VALUE(RIGHT(P10,LEN(P10)-SEARCH("/",P10))) -> 295 | R10: =VALUE(SUBSTITUTE(LEFT(P10,SEARCH("/",P10)-1),"+",",")) -> 145.473 | S10: Ouargla / OUARGLA | T10: =CONCATENATE("(",A10,",'",E10,"','",F10,"','",TEXT(G10,"aaaa-mm-jj"),"','",TEXT(H10,"aaaa-mm-jj"),"',",TEXT(I10,"aaaa-mm-jj"),",",J10,",",M10,"),") -> (4,'PS-04-OZ1','Poste de Sectionnement n°04 OZ1','Sunday-11-jj','Sunday-11-jj',NULL,1,16),
A11: 5 | B11: 9 | C11: OZ1/OZ2 | D11: 1 | E11: =CONCATENATE("PS-",TEXT(A11,"00"),"-",O11) -> PS-05-OZ1 | F11: =CONCATENATE("Poste de Sectionnement n°",TEXT(A11,"00")," ",O11) -> Poste de Sectionnement n°05 OZ1 | G11: 24053 | H11: 24053 | I11: NULL | J11: 1 | K11: Sectionalizing Station | L11: 16 | M11: 16 | O11: OZ1 | P11: 184+200 / 365 | Q11: =VALUE(RIGHT(P11,LEN(P11)-SEARCH("/",P11))) -> 365 | R11: =VALUE(SUBSTITUTE(LEFT(P11,SEARCH("/",P11)-1),"+",",")) -> 184.2 | S11: Zelfana / GHARDAIA | T11: =CONCATENATE("(",A11,",'",E11,"','",F11,"','",TEXT(G11,"aaaa-mm-jj"),"','",TEXT(H11,"aaaa-mm-jj"),"',",TEXT(I11,"aaaa-mm-jj"),",",J11,",",M11,"),") -> (5,'PS-05-OZ1','Poste de Sectionnement n°05 OZ1','Sunday-11-jj','Sunday-11-jj',NULL,1,16),
A12: 3 | B12: 10 | C12: OZ1/OZ2 | D12: 1 | E12: =CONCATENATE("PC-",TEXT(A12,"00"),"-",O12) -> PC-03-OZ1 | F12: =CONCATENATE("Poste de Coupure n°",TEXT(A12,"00")," ",O12) -> Poste de Coupure n°03 OZ1 | G12: 24053 | H12: 24053 | I12: NULL | J12: 1 | K12: Block Valve Station | L12: 15 | M12: 16 | O12: OZ1 | P12: 218+075 / 495 | Q12: =VALUE(RIGHT(P12,LEN(P12)-SEARCH("/",P12))) -> 495 | R12: =VALUE(SUBSTITUTE(LEFT(P12,SEARCH("/",P12)-1),"+",",")) -> 218.075 | S12: Al Atteuf / GHARDAIA | T12: =CONCATENATE("(",A12,",'",E12,"','",F12,"','",TEXT(G12,"aaaa-mm-jj"),"','",TEXT(H12,"aaaa-mm-jj"),"',",TEXT(I12,"aaaa-mm-jj"),",",J12,",",M12,"),") -> (3,'PC-03-OZ1','Poste de Coupure n°03 OZ1','Sunday-11-jj','Sunday-11-jj',NULL,1,16),
A13: 10 | B13: 11 | C13: OZ1/OZ2 | D13: 1 | E13: SP3-OZ1-D | F13: =CONCATENATE("Station de Pompage ",E13) -> Station de Pompage SP3-OZ1-D | G13: 23743 | H13: 23743 | I13: 37986 | J13: 8 | K13: Pumping Station | L13: 7 | M13: 16 | O13: OZ1 | P13: 218+075 / 495 | Q13: =VALUE(RIGHT(P13,LEN(P13)-SEARCH("/",P13))) -> 495 | R13: =VALUE(SUBSTITUTE(LEFT(P13,SEARCH("/",P13)-1),"+",",")) -> 218.075 | S13: Al Atteuf / GHARDAIA | T13: =CONCATENATE("(",A13,",'",E13,"','",F13,"','",TEXT(G13,"aaaa-mm-jj"),"','",TEXT(H13,"aaaa-mm-jj"),"',",TEXT(I13,"aaaa-mm-jj"),",",J13,",",M13,"),") -> (10,'SP3-OZ1-D','Station de Pompage SP3-OZ1-D','Friday-01-jj','Friday-01-jj',Wednesday-12-jj,8,16),
A14: 6 | B14: 12 | C14: OZ1/OZ2 | D14: 1 | E14: =CONCATENATE("PS-",TEXT(A14,"00"),"-",O14) -> PS-06-OZ1 | F14: =CONCATENATE("Poste de Sectionnement n°",TEXT(A14,"00")," ",O14) -> Poste de Sectionnement n°06 OZ1 | G14: 24053 | H14: 24053 | I14: NULL | J14: 1 | K14: Sectionalizing Station | L14: 16 | M14: 16 | O14: OZ1 | P14: 236+475 / 562 | Q14: =VALUE(RIGHT(P14,LEN(P14)-SEARCH("/",P14))) -> 562 | R14: =VALUE(SUBSTITUTE(LEFT(P14,SEARCH("/",P14)-1),"+",",")) -> 236.475 | S14: Ghardaia / GHARDAIA | T14: =CONCATENATE("(",A14,",'",E14,"','",F14,"','",TEXT(G14,"aaaa-mm-jj"),"','",TEXT(H14,"aaaa-mm-jj"),"',",TEXT(I14,"aaaa-mm-jj"),",",J14,",",M14,"),") -> (6,'PS-06-OZ1','Poste de Sectionnement n°06 OZ1','Sunday-11-jj','Sunday-11-jj',NULL,1,16),
A15: 7 | B15: 13 | C15: OZ1/OZ2 | D15: 1 | E15: =CONCATENATE("PS-",TEXT(A15,"00"),"-",O15) -> PS-07-OZ1 | F15: =CONCATENATE("Poste de Sectionnement n°",TEXT(A15,"00")," ",O15) -> Poste de Sectionnement n°07 OZ1 | G15: 24053 | H15: 24053 | I15: NULL | J15: 1 | K15: Sectionalizing Station | L15: 16 | M15: 16 | O15: OZ1 | P15: 256+000 / 631 | Q15: =VALUE(RIGHT(P15,LEN(P15)-SEARCH("/",P15))) -> 631 | R15: =VALUE(SUBSTITUTE(LEFT(P15,SEARCH("/",P15)-1),"+",",")) -> 256 | S15: Daia Ben Dahoua / GHARDAIA | T15: =CONCATENATE("(",A15,",'",E15,"','",F15,"','",TEXT(G15,"aaaa-mm-jj"),"','",TEXT(H15,"aaaa-mm-jj"),"',",TEXT(I15,"aaaa-mm-jj"),",",J15,",",M15,"),") -> (7,'PS-07-OZ1','Poste de Sectionnement n°07 OZ1','Sunday-11-jj','Sunday-11-jj',NULL,1,16),
A16: 4 | B16: 14 | C16: OZ1/OZ2 | D16: 1 | E16: =CONCATENATE("PC-",TEXT(A16,"00"),"-",O16) -> PC-04-OZ1 | F16: =CONCATENATE("Poste de Coupure n°",TEXT(A16,"00")," ",O16) -> Poste de Coupure n°04 OZ1 | G16: 24053 | H16: 24053 | I16: NULL | J16: 1 | K16: Block Valve Station | L16: 15 | M16: 11 | O16: OZ1 | P16: 306+000 / 777 | Q16: =VALUE(RIGHT(P16,LEN(P16)-SEARCH("/",P16))) -> 777 | R16: =VALUE(SUBSTITUTE(LEFT(P16,SEARCH("/",P16)-1),"+",",")) -> 306 | S16: Hassi R’Mel / LAGHOUAT | T16: =CONCATENATE("(",A16,",'",E16,"','",F16,"','",TEXT(G16,"aaaa-mm-jj"),"','",TEXT(H16,"aaaa-mm-jj"),"',",TEXT(I16,"aaaa-mm-jj"),",",J16,",",M16,"),") -> (4,'PC-04-OZ1','Poste de Coupure n°04 OZ1','Sunday-11-jj','Sunday-11-jj',NULL,1,11),
A17: 11 | B17: 15 | C17: OZ1/OZ2 | D17: 1 | E17: SP4-OZ1-D | F17: =CONCATENATE("Station de Pompage ",E17) -> Station de Pompage SP4-OZ1-D | G17: 23743 | H17: 23743 | I17: 38352 | J17: 8 | K17: Pumping Station | L17: 7 | M17: 11 | O17: OZ1 | P17: 306+000 / 777 | Q17: =VALUE(RIGHT(P17,LEN(P17)-SEARCH("/",P17))) -> 777 | R17: =VALUE(SUBSTITUTE(LEFT(P17,SEARCH("/",P17)-1),"+",",")) -> 306 | S17: Hassi R’Mel / LAGHOUAT | T17: =CONCATENATE("(",A17,",'",E17,"','",F17,"','",TEXT(G17,"aaaa-mm-jj"),"','",TEXT(H17,"aaaa-mm-jj"),"',",I17,",",J17,",",M17,"),") -> (11,'SP4-OZ1-D','Station de Pompage SP4-OZ1-D','Friday-01-jj','Friday-01-jj',38352,8,11),
A18: 8 | B18: 16 | C18: OZ1/OZ2 | D18: 1 | E18: =CONCATENATE("PS-",TEXT(A18,"00"),"-",O18) -> PS-08-OZ1 | F18: =CONCATENATE("Poste de Sectionnement n°",TEXT(A18,"00")," ",O18) -> Poste de Sectionnement n°08 OZ1 | G18: 24053 | H18: 24053 | I18: NULL | J18: 1 | K18: Sectionalizing Station | L18: 16 | M18: 11 | O18: OZ1 | P18: 328+047 / 762 | Q18: =VALUE(RIGHT(P18,LEN(P18)-SEARCH("/",P18))) -> 762 | R18: =VALUE(SUBSTITUTE(LEFT(P18,SEARCH("/",P18)-1),"+",",")) -> 328.047 | S18: Hassi / R'mel / LAGHOUAT | T18: =CONCATENATE("(",A18,",'",E18,"','",F18,"','",TEXT(G18,"aaaa-mm-jj"),"','",TEXT(H18,"aaaa-mm-jj"),"',",I18,",",J18,",",M18,"),") -> (8,'PS-08-OZ1','Poste de Sectionnement n°08 OZ1','Sunday-11-jj','Sunday-11-jj',NULL,1,11),
A19: 5 | B19: 17 | C19: OZ1/OZ2 | D19: 1 | E19: =CONCATENATE("PC-",TEXT(A19,"00"),"-",O19) -> PC-05-OZ1 | F19: =CONCATENATE("Poste de Coupure n°",TEXT(A19,"00")," ",O19) -> Poste de Coupure n°05 OZ1 | G19: 24053 | H19: 24053 | I19: NULL | J19: 1 | K19: Block Valve Station | L19: 15 | M19: 11 | O19: OZ1 | P19: 415+100 / 885 | Q19: =VALUE(RIGHT(P19,LEN(P19)-SEARCH("/",P19))) -> 885 | R19: =VALUE(SUBSTITUTE(LEFT(P19,SEARCH("/",P19)-1),"+",",")) -> 415.1 | S19: Milok / Tadjemout / LAGHOUAT | T19: =CONCATENATE("(",A19,",'",E19,"','",F19,"','",TEXT(G19,"aaaa-mm-jj"),"','",TEXT(H19,"aaaa-mm-jj"),"',",I19,",",J19,",",M19,"),") -> (5,'PC-05-OZ1','Poste de Coupure n°05 OZ1','Sunday-11-jj','Sunday-11-jj',NULL,1,11),
A20: 12 | B20: 18 | C20: OZ1/OZ2 | D20: 1 | E20: SP5-OZ1-D | F20: =CONCATENATE("Station de Pompage ",E20) -> Station de Pompage SP5-OZ1-D | G20: 23743 | H20: 23743 | I20: 40178 | J20: 8 | K20: Pumping Station | L20: 7 | M20: 11 | O20: OZ1 | P20: 415+100 / 885 | Q20: =VALUE(RIGHT(P20,LEN(P20)-SEARCH("/",P20))) -> 885 | R20: =VALUE(SUBSTITUTE(LEFT(P20,SEARCH("/",P20)-1),"+",",")) -> 415.1 | S20: Milok / Tadjemout / LAGHOUAT | T20: =CONCATENATE("(",A20,",'",E20,"','",F20,"','",TEXT(G20,"aaaa-mm-jj"),"','",TEXT(H20,"aaaa-mm-jj"),"',",I20,",",J20,",",M20,"),") -> (12,'SP5-OZ1-D','Station de Pompage SP5-OZ1-D','Friday-01-jj','Friday-01-jj',40178,8,11),
A21: 9 | B21: 19 | C21: OZ1/OZ2 | D21: 1 | E21: =CONCATENATE("PS-",TEXT(A21,"00"),"-",O21) -> PS-09-OZ1 | F21: =CONCATENATE("Poste de Sectionnement n°",TEXT(A21,"00")," ",O21) -> Poste de Sectionnement n°09 OZ1 | G21: 24053 | H21: 24053 | I21: NULL | J21: 1 | K21: Sectionalizing Station | L21: 16 | M21: 11 | O21: OZ1 | P21: 466+900 / 1275 | Q21: =VALUE(RIGHT(P21,LEN(P21)-SEARCH("/",P21))) -> 1275 | R21: =VALUE(SUBSTITUTE(LEFT(P21,SEARCH("/",P21)-1),"+",",")) -> 466.9 | S21: Ain Hamra / LAGHOUAT | T21: =CONCATENATE("(",A21,",'",E21,"','",F21,"','",TEXT(G21,"aaaa-mm-jj"),"','",TEXT(H21,"aaaa-mm-jj"),"',",I21,",",J21,",",M21,"),") -> (9,'PS-09-OZ1','Poste de Sectionnement n°09 OZ1','Sunday-11-jj','Sunday-11-jj',NULL,1,11),
A22: 10 | B22: 20 | C22: OZ1/OZ2 | D22: 1 | E22: =CONCATENATE("PS-",TEXT(A22,"00"),"-",O22) -> PS-10-OZ1 | F22: =CONCATENATE("Poste de Sectionnement n°",TEXT(A22,"00")," ",O22) -> Poste de Sectionnement n°10 OZ1 | G22: 24053 | H22: 24053 | I22: NULL | J22: 1 | K22: Sectionalizing Station | L22: 16 | M22: 11 | O22: OZ1 | P22: 489+915 / 1083 | Q22: =VALUE(RIGHT(P22,LEN(P22)-SEARCH("/",P22))) -> 1083 | R22: =VALUE(SUBSTITUTE(LEFT(P22,SEARCH("/",P22)-1),"+",",")) -> 489.915 | S22: Djelfa / DJELFA | T22: =CONCATENATE("(",A22,",'",E22,"','",F22,"','",TEXT(G22,"aaaa-mm-jj"),"','",TEXT(H22,"aaaa-mm-jj"),"',",I22,",",J22,",",M22,"),") -> (10,'PS-10-OZ1','Poste de Sectionnement n°10 OZ1','Sunday-11-jj','Sunday-11-jj',NULL,1,11),
A23: 11 | B23: 21 | C23: OZ1/OZ2 | D23: 1 | E23: =CONCATENATE("PS-",TEXT(A23,"00"),"-",O23) -> PS-11-OZ1 | F23: =CONCATENATE("Poste de Sectionnement n°",TEXT(A23,"00")," ",O23) -> Poste de Sectionnement n°11 OZ1 | G23: 24053 | H23: 24053 | I23: NULL | J23: 1 | K23: Sectionalizing Station | L23: 16 | M23: 11 | O23: OZ1 | P23: 533+940 / 970 | Q23: =VALUE(RIGHT(P23,LEN(P23)-SEARCH("/",P23))) -> 970 | R23: =VALUE(SUBSTITUTE(LEFT(P23,SEARCH("/",P23)-1),"+",",")) -> 533.94 | S23: Faidja / TIARET | T23: =CONCATENATE("(",A23,",'",E23,"','",F23,"','",TEXT(G23,"aaaa-mm-jj"),"','",TEXT(H23,"aaaa-mm-jj"),"',",I23,",",J23,",",M23,"),") -> (11,'PS-11-OZ1','Poste de Sectionnement n°11 OZ1','Sunday-11-jj','Sunday-11-jj',NULL,1,11),
A24: 12 | B24: 22 | C24: OZ1/OZ2 | D24: 1 | E24: =CONCATENATE("PS-",TEXT(A24,"00"),"-",O24) -> PS-12-OZ1 | F24: =CONCATENATE("Poste de Sectionnement n°",TEXT(A24,"00")," ",O24) -> Poste de Sectionnement n°12 OZ1 | G24: 24053 | H24: 24053 | I24: NULL | J24: 1 | K24: Sectionalizing Station | L24: 16 | M24: 11 | O24: OZ1 | P24: 534+060 /970 | Q24: =VALUE(RIGHT(P24,LEN(P24)-SEARCH("/",P24))) -> 970 | R24: =VALUE(SUBSTITUTE(LEFT(P24,SEARCH("/",P24)-1),"+",",")) -> 534.06 | S24: Faidja / TIARET | T24: =CONCATENATE("(",A24,",'",E24,"','",F24,"','",TEXT(G24,"aaaa-mm-jj"),"','",TEXT(H24,"aaaa-mm-jj"),"',",I24,",",J24,",",M24,"),") -> (12,'PS-12-OZ1','Poste de Sectionnement n°12 OZ1','Sunday-11-jj','Sunday-11-jj',NULL,1,11),
A25: 6 | B25: 23 | C25: OZ1/OZ2 | D25: 1 | E25: =CONCATENATE("PC-",TEXT(A25,"00"),"-",O25) -> PC-06-OZ1 | F25: =CONCATENATE("Poste de Coupure n°",TEXT(A25,"00")," ",O25) -> Poste de Coupure n°06 OZ1 | G25: 24053 | H25: 24053 | I25: NULL | J25: 1 | K25: Block Valve Station | L25: 15 | M25: 11 | O25: OZ1 | P25: 534+900 / 973 | Q25: =VALUE(RIGHT(P25,LEN(P25)-SEARCH("/",P25))) -> 973 | R25: =VALUE(SUBSTITUTE(LEFT(P25,SEARCH("/",P25)-1),"+",",")) -> 534.9 | S25: Djebil / Faidja / TIARET | T25: =CONCATENATE("(",A25,",'",E25,"','",F25,"','",TEXT(G25,"aaaa-mm-jj"),"','",TEXT(H25,"aaaa-mm-jj"),"',",I25,",",J25,",",M25,"),") -> (6,'PC-06-OZ1','Poste de Coupure n°06 OZ1','Sunday-11-jj','Sunday-11-jj',NULL,1,11),
A26: 13 | B26: 24 | C26: OZ1/OZ2 | D26: 1 | E26: SP6-OZ1-D | F26: =CONCATENATE("Station de Pompage ",E26) -> Station de Pompage SP6-OZ1-D | G26: 23743 | H26: 23743 | I26: 38352 | J26: 8 | K26: Pumping Station | L26: 7 | M26: 11 | O26: OZ1 | P26: 534+900 / 973 | Q26: =VALUE(RIGHT(P26,LEN(P26)-SEARCH("/",P26))) -> 973 | R26: =VALUE(SUBSTITUTE(LEFT(P26,SEARCH("/",P26)-1),"+",",")) -> 534.9 | S26: Djebil / Faidja / TIARET | T26: =CONCATENATE("(",A26,",'",E26,"','",F26,"','",TEXT(G26,"aaaa-mm-jj"),"','",TEXT(H26,"aaaa-mm-jj"),"',",I26,",",J26,",",M26,"),") -> (13,'SP6-OZ1-D','Station de Pompage SP6-OZ1-D','Friday-01-jj','Friday-01-jj',38352,8,11),
A27: 13 | B27: 25 | C27: OZ1/OZ2 | D27: 1 | E27: =CONCATENATE("PS-",TEXT(A27,"00"),"-",O27) -> PS-13-OZ1 | F27: =CONCATENATE("Poste de Sectionnement n°",TEXT(A27,"00")," ",O27) -> Poste de Sectionnement n°13 OZ1 | G27: 24053 | H27: 24053 | I27: NULL | J27: 1 | K27: Sectionalizing Station | L27: 16 | M27: 11 | O27: OZ1 | P27: 552+122 /1100 | Q27: =VALUE(RIGHT(P27,LEN(P27)-SEARCH("/",P27))) -> 1100 | R27: =VALUE(SUBSTITUTE(LEFT(P27,SEARCH("/",P27)-1),"+",",")) -> 552.122 | S27: Ain Dheb / TIARET | T27: =CONCATENATE("(",A27,",'",E27,"','",F27,"','",TEXT(G27,"aaaa-mm-jj"),"','",TEXT(H27,"aaaa-mm-jj"),"',",TEXT(I27,"aaaa-mm-jj"),",",J27,",",M27,"),") -> (13,'PS-13-OZ1','Poste de Sectionnement n°13 OZ1','Sunday-11-jj','Sunday-11-jj',NULL,1,11),
A28: 14 | B28: 26 | C28: OZ1/OZ2 | D28: 1 | E28: =CONCATENATE("PS-",TEXT(A28,"00"),"-",O28) -> PS-14-OZ1 | F28: =CONCATENATE("Poste de Sectionnement n°",TEXT(A28,"00")," ",O28) -> Poste de Sectionnement n°14 OZ1 | G28: 24053 | H28: 24053 | I28: NULL | J28: 1 | K28: Sectionalizing Station | L28: 16 | M28: 11 | O28: OZ1 | P28: 611+375 / 1100 | Q28: =VALUE(RIGHT(P28,LEN(P28)-SEARCH("/",P28))) -> 1100 | R28: =VALUE(SUBSTITUTE(LEFT(P28,SEARCH("/",P28)-1),"+",",")) -> 611.375 | S28: Sougueur / TIARET | T28: =CONCATENATE("(",A28,",'",E28,"','",F28,"','",TEXT(G28,"aaaa-mm-jj"),"','",TEXT(H28,"aaaa-mm-jj"),"',",TEXT(I28,"aaaa-mm-jj"),",",J28,",",M28,"),") -> (14,'PS-14-OZ1','Poste de Sectionnement n°14 OZ1','Sunday-11-jj','Sunday-11-jj',NULL,1,11),
A29: 15 | B29: 27 | C29: OZ1/OZ2 | D29: 1 | E29: =CONCATENATE("PS-",TEXT(A29,"00"),"-",O29) -> PS-15-OZ1 | F29: =CONCATENATE("Poste de Sectionnement n°",TEXT(A29,"00")," ",O29) -> Poste de Sectionnement n°15 OZ1 | G29: 24053 | H29: 24053 | I29: NULL | J29: 1 | K29: Sectionalizing Station | L29: 16 | M29: 11 | O29: OZ1 | P29: 648+000 / 758 | Q29: =VALUE(RIGHT(P29,LEN(P29)-SEARCH("/",P29))) -> 758 | R29: =VALUE(SUBSTITUTE(LEFT(P29,SEARCH("/",P29)-1),"+",",")) -> 648 | S29: Guertoufa / TIARET | T29: =CONCATENATE("(",A29,",'",E29,"','",F29,"','",TEXT(G29,"aaaa-mm-jj"),"','",TEXT(H29,"aaaa-mm-jj"),"',",TEXT(I29,"aaaa-mm-jj"),",",J29,",",M29,"),") -> (15,'PS-15-OZ1','Poste de Sectionnement n°15 OZ1','Sunday-11-jj','Sunday-11-jj',NULL,1,11),
A30: 16 | B30: 28 | C30: OZ1/OZ2 | D30: 1 | E30: =CONCATENATE("PS-",TEXT(A30,"00"),"-",O30) -> PS-16-OZ1 | F30: =CONCATENATE("Poste de Sectionnement n°",TEXT(A30,"00")," ",O30) -> Poste de Sectionnement n°16 OZ1 | G30: 24053 | H30: 24053 | I30: NULL | J30: 1 | K30: Sectionalizing Station | L30: 16 | M30: 11 | O30: OZ1 | P30: 669+302 / 620 | Q30: =VALUE(RIGHT(P30,LEN(P30)-SEARCH("/",P30))) -> 620 | R30: =VALUE(SUBSTITUTE(LEFT(P30,SEARCH("/",P30)-1),"+",",")) -> 669.302 | S30: Rahouia / TIARET | T30: =CONCATENATE("(",A30,",'",E30,"','",F30,"','",TEXT(G30,"aaaa-mm-jj"),"','",TEXT(H30,"aaaa-mm-jj"),"',",TEXT(I30,"aaaa-mm-jj"),",",J30,",",M30,"),") -> (16,'PS-16-OZ1','Poste de Sectionnement n°16 OZ1','Sunday-11-jj','Sunday-11-jj',NULL,1,11),
A31: 17 | B31: 29 | C31: OZ1/OZ2 | D31: 1 | E31: =CONCATENATE("PS-",TEXT(A31,"00"),"-",O31) -> PS-17-OZ1 | F31: =CONCATENATE("Poste de Sectionnement n°",TEXT(A31,"00")," ",O31) -> Poste de Sectionnement n°17 OZ1 | G31: 24053 | H31: 24053 | I31: NULL | J31: 1 | K31: Sectionalizing Station | L31: 16 | M31: 11 | O31: OZ1 | P31: 701+544 / 270 | Q31: =VALUE(RIGHT(P31,LEN(P31)-SEARCH("/",P31))) -> 270 | R31: =VALUE(SUBSTITUTE(LEFT(P31,SEARCH("/",P31)-1),"+",",")) -> 701.544 | S31: Zemmoura / RELIZANE | T31: =CONCATENATE("(",A31,",'",E31,"','",F31,"','",TEXT(G31,"aaaa-mm-jj"),"','",TEXT(H31,"aaaa-mm-jj"),"',",TEXT(I31,"aaaa-mm-jj"),",",J31,",",M31,"),") -> (17,'PS-17-OZ1','Poste de Sectionnement n°17 OZ1','Sunday-11-jj','Sunday-11-jj',NULL,1,11),
A32: 14 | B32: 30 | C32: OZ1/OZ2 | D32: 1 | E32: PRS-OZ1-D | F32: Station de Régulation PRS-OZ1-D | G32: 23743 | H32: 23743 | I32: 43465 | J32: 8 | K32: Regulator Station | L32: 9 | M32: 11 | O32: OZ1 | P32: 705+573 / 498 | Q32: =VALUE(RIGHT(P32,LEN(P32)-SEARCH("/",P32))) -> 498 | R32: =VALUE(SUBSTITUTE(LEFT(P32,SEARCH("/",P32)-1),"+",",")) -> 705.573 | S32: Kenanda / Relizane | T32: =CONCATENATE("(",A32,",'",E32,"','",F32,"','",TEXT(G32,"aaaa-mm-jj"),"','",TEXT(H32,"aaaa-mm-jj"),"',",TEXT(I32,"aaaa-mm-jj"),",",J32,",",M32,"),") -> (14,'PRS-OZ1-D','Station de Régulation PRS-OZ1-D','Friday-01-jj','Friday-01-jj',Monday-12-jj,8,11),
A33: 18 | B33: 31 | C33: OZ1/OZ2 | D33: 1 | E33: =CONCATENATE("PS-",TEXT(A33,"00"),"-",O33) -> PS-18-OZ1 | F33: =CONCATENATE("Poste de Sectionnement n°",TEXT(A33,"00")," ",O33) -> Poste de Sectionnement n°18 OZ1 | G33: 24053 | H33: 24053 | I33: NULL | J33: 1 | K33: Sectionalizing Station | L33: 16 | M33: 11 | O33: OZ1 | P33: 715+885 / 87 | Q33: =VALUE(RIGHT(P33,LEN(P33)-SEARCH("/",P33))) -> 87 | R33: =VALUE(SUBSTITUTE(LEFT(P33,SEARCH("/",P33)-1),"+",",")) -> 715.885 | S33: Bormadia / RELIZANE | T33: =CONCATENATE("(",A33,",'",E33,"','",F33,"','",TEXT(G33,"aaaa-mm-jj"),"','",TEXT(H33,"aaaa-mm-jj"),"',",TEXT(I33,"aaaa-mm-jj"),",",J33,",",M33,"),") -> (18,'PS-18-OZ1','Poste de Sectionnement n°18 OZ1','Sunday-11-jj','Sunday-11-jj',NULL,1,11),
A34: 19 | B34: 32 | C34: OZ1/OZ2 | D34: 1 | E34: =CONCATENATE("PS-",TEXT(A34,"00"),"-",O34) -> PS-19-OZ1 | F34: =CONCATENATE("Poste de Sectionnement n°",TEXT(A34,"00")," ",O34) -> Poste de Sectionnement n°19 OZ1 | G34: 24053 | H34: 24053 | I34: NULL | J34: 1 | K34: Sectionalizing Station | L34: 16 | M34: 11 | O34: OZ1 | P34: 758+279 / 25 | Q34: =VALUE(RIGHT(P34,LEN(P34)-SEARCH("/",P34))) -> 25 | R34: =VALUE(SUBSTITUTE(LEFT(P34,SEARCH("/",P34)-1),"+",",")) -> 758.279 | S34: El Hassiane / MOSTAGANEM | T34: =CONCATENATE("(",A34,",'",E34,"','",F34,"','",TEXT(G34,"aaaa-mm-jj"),"','",TEXT(H34,"aaaa-mm-jj"),"',",TEXT(I34,"aaaa-mm-jj"),",",J34,",",M34,"),") -> (19,'PS-19-OZ1','Poste de Sectionnement n°19 OZ1','Sunday-11-jj','Sunday-11-jj',NULL,1,11),
A35: 20 | B35: 33 | C35: OZ1/OZ2 | D35: 1 | E35: =CONCATENATE("PS-",TEXT(A35,"00"),"-",O35) -> PS-20-OZ1 | F35: =CONCATENATE("Poste de Sectionnement n°",TEXT(A35,"00")," ",O35) -> Poste de Sectionnement n°20 OZ1 | G35: 24053 | H35: 24053 | I35: NULL | J35: 1 | K35: Sectionalizing Station | L35: 16 | M35: 11 | O35: OZ1 | P35: 781+594 / 08 | Q35: =VALUE(RIGHT(P35,LEN(P35)-SEARCH("/",P35))) -> 8 | R35: =VALUE(SUBSTITUTE(LEFT(P35,SEARCH("/",P35)-1),"+",",")) -> 781.594 | S35: El Hassiane / MOSTAGANEM | T35: =CONCATENATE("(",A35,",'",E35,"','",F35,"','",TEXT(G35,"aaaa-mm-jj"),"','",TEXT(H35,"aaaa-mm-jj"),"',",TEXT(I35,"aaaa-mm-jj"),",",J35,",",M35,"),") -> (20,'PS-20-OZ1','Poste de Sectionnement n°20 OZ1','Sunday-11-jj','Sunday-11-jj',NULL,1,11),
A36: 21 | B36: 34 | C36: OZ1/OZ2 | D36: 1 | E36: =CONCATENATE("PS-",TEXT(A36,"00"),"-",O36) -> PS-21-OZ1 | F36: =CONCATENATE("Poste de Sectionnement n°",TEXT(A36,"00")," ",O36) -> Poste de Sectionnement n°21 OZ1 | G36: 24053 | H36: 24053 | I36: NULL | J36: 1 | K36: Sectionalizing Station | L36: 16 | M36: 11 | O36: OZ1 | P36: 781+720 / 08 | Q36: =VALUE(RIGHT(P36,LEN(P36)-SEARCH("/",P36))) -> 8 | R36: =VALUE(SUBSTITUTE(LEFT(P36,SEARCH("/",P36)-1),"+",",")) -> 781.72 | S36: Marsa el hadjej / ORAN | T36: =CONCATENATE("(",A36,",'",E36,"','",F36,"','",TEXT(G36,"aaaa-mm-jj"),"','",TEXT(H36,"aaaa-mm-jj"),"',",I36,",",J36,",",M36,"),") -> (21,'PS-21-OZ1','Poste de Sectionnement n°21 OZ1','Sunday-11-jj','Sunday-11-jj',NULL,1,11),
A37: 1 | B37: 35 | C37: OZ1/OZ2 | D37: 1 | E37: =CONCATENATE("PC-",TEXT(A37,"00"),"-",O37) -> PC-01-OZ2 | F37: =CONCATENATE("Poste de Coupure n°",TEXT(A37,"00")," ",O37) -> Poste de Coupure n°01 OZ2 | G37: 37851 | H37: 37851 | I37: NULL | J37: 1 | K37: Block Valve Station | L37: 15 | M37: 16 | O37: OZ2 | P37: 0 / 169 | Q37: =VALUE(RIGHT(P37,LEN(P37)-SEARCH("/",P37))) -> 169 | R37: =VALUE(SUBSTITUTE(LEFT(P37,SEARCH("/",P37)-1),"+",",")) -> 0 | S37: Hassi Messaoud / OUARGLA | T37: =CONCATENATE("(",A37,",'",E37,"','",F37,"','",TEXT(G37,"aaaa-mm-jj"),"','",TEXT(H37,"aaaa-mm-jj"),"',",I37,",",J37,",",M37,"),") -> (1,'PC-01-OZ2','Poste de Coupure n°01 OZ2','Monday-08-jj','Monday-08-jj',NULL,1,16),
A38: 1 | B38: 36 | C38: OZ1/OZ2 | D38: 1 | E38: SP1-OZ1/OZ2 | F38: =CONCATENATE("Station de Pompage ",E38) -> Station de Pompage SP1-OZ1/OZ2 | G38: 36540 | H38: 37154 | I38: NULL | J38: 1 | K38: Pumping Station | L38: 7 | M38: 16 | O38: OZ2 | P38: 0 / 156 | Q38: =VALUE(RIGHT(P38,LEN(P38)-SEARCH("/",P38))) -> 156 | R38: =VALUE(SUBSTITUTE(LEFT(P38,SEARCH("/",P38)-1),"+",",")) -> 0 | S38: Hassi Messaoud / OUARGLA | T38: =CONCATENATE("(",A38,",'",E38,"','",F38,"','",TEXT(G38,"aaaa-mm-jj"),"','",TEXT(H38,"aaaa-mm-jj"),"',",I38,",",J38,",",M38,"),") -> (1,'SP1-OZ1/OZ2','Station de Pompage SP1-OZ1/OZ2','Saturday-01-jj','Thursday-09-jj',NULL,1,16),
A39: 1 | B39: 37 | C39: OZ1/OZ2 | D39: 1 | E39: =CONCATENATE("PS-",TEXT(A39,"00"),"-",O39) -> PS-01-OZ2 | F39: =CONCATENATE("Poste de Sectionnement n°",TEXT(A39,"00")," ",O39) -> Poste de Sectionnement n°01 OZ2 | G39: 37851 | H39: 37851 | I39: NULL | J39: 1 | K39: Sectionalizing Station | L39: 16 | M39: 16 | O39: OZ2 | P39: 22+000 / 142 | Q39: =VALUE(RIGHT(P39,LEN(P39)-SEARCH("/",P39))) -> 142 | R39: =VALUE(SUBSTITUTE(LEFT(P39,SEARCH("/",P39)-1),"+",",")) -> 22 | S39: Hassi Ben Abdellah /OUARGLA | T39: =CONCATENATE("(",A39,",'",E39,"','",F39,"','",TEXT(G39,"aaaa-mm-jj"),"','",TEXT(H39,"aaaa-mm-jj"),"',",I39,",",J39,",",M39,"),") -> (1,'PS-01-OZ2','Poste de Sectionnement n°01 OZ2','Monday-08-jj','Monday-08-jj',NULL,1,16),
A40: 2 | B40: 38 | C40: OZ1/OZ2 | D40: 1 | E40: =CONCATENATE("PS-",TEXT(A40,"00"),"-",O40) -> PS-02-OZ2 | F40: =CONCATENATE("Poste de Sectionnement n°",TEXT(A40,"00")," ",O40) -> Poste de Sectionnement n°02 OZ2 | G40: 37851 | H40: 37851 | I40: NULL | J40: 1 | K40: Sectionalizing Station | L40: 16 | M40: 16 | O40: OZ2 | P40: 43+900 / 149 | Q40: =VALUE(RIGHT(P40,LEN(P40)-SEARCH("/",P40))) -> 149 | R40: =VALUE(SUBSTITUTE(LEFT(P40,SEARCH("/",P40)-1),"+",",")) -> 43.9 | S40: Ain Beida /OUARGLA | T40: =CONCATENATE("(",A40,",'",E40,"','",F40,"','",TEXT(G40,"aaaa-mm-jj"),"','",TEXT(H40,"aaaa-mm-jj"),"',",I40,",",J40,",",M40,"),") -> (2,'PS-02-OZ2','Poste de Sectionnement n°02 OZ2','Monday-08-jj','Monday-08-jj',NULL,1,16),
...

Sheet 02-03-03-ST
A1: Id | B1: System | C1: SystemId | D1: Code | E1: Name | F1: Installing | G1: Commissioning | H1: Decommissioning | I1: Status | J1: StationType | K1: StTypeId | L1: Structure | M1: SQL Insert Request
A2: F_00 | D2: F_01 | E2: F_02 | F2: F_03 | G2: F_04 | H2: F_05 | I2: F_06 | L2: F_07 | M2: INSERT INTO T_02_03_01 (F_00, F_01, F_02, F_03, F_04, F_05, F_06, F_07) VALUES
A3: 41 | B3: OZ1/OZ2 | C3: =_xlfn.XLOOKUP(B3,'02-03-07'!B$3:B$24,'02-03-07'!A$3:A$24) -> #NAME? | D3: SP1-OZ1/OZ2 | E3: Station de Pompage SP1-OZ1/OZ2 | F3: 36540 | G3: 37154 | H3: NULL | I3: 1 | J3: Pumping Station | K3: 7 | L3: 10 | M3: =CONCATENATE("(",A3,",'",D3,"','",E3,"','",TEXT(F3,"yyyy-mm-dd"),"','",TEXT(G3,"yyyy-mm-dd"),"',",H3,",",I3,",",L3,"),") -> (41,'SP1-OZ1/OZ2','Station de Pompage SP1-OZ1/OZ2','2000-01-15','2001-09-20',NULL,1,10),
A4: 42 | B4: OZ1/OZ2 | C4: =_xlfn.XLOOKUP(B4,'02-03-07'!B$3:B$24,'02-03-07'!A$3:A$24) -> #NAME? | D4: SP2-OZ1/OZ2 | E4: Station de Pompage SP2-OZ1/OZ2 | F4: 36960 | G4: 37575 | H4: NULL | I4: 1 | J4: Pumping Station | K4: 7 | L4: 10 | M4: =CONCATENATE("(",A4,",'",D4,"','",E4,"','",TEXT(F4,"yyyy-mm-dd"),"','",TEXT(G4,"yyyy-mm-dd"),"',",H4,",",I4,",",L4,"),") -> (42,'SP2-OZ1/OZ2','Station de Pompage SP2-OZ1/OZ2','2001-03-10','2002-11-15',NULL,1,10),
A5: 43 | B5: OZ1/OZ2 | C5: =_xlfn.XLOOKUP(B5,'02-03-07'!B$3:B$24,'02-03-07'!A$3:A$24) -> #NAME? | D5: SP3-OZ1/OZ2 | E5: Station de Pompage SP2-OZ1/OZ2 | F5: 37396 | G5: 37985 | H5: NULL | I5: 1 | J5: Pumping Station | K5: 7 | L5: 10 | M5: =CONCATENATE("(",A5,",'",D5,"','",E5,"','",TEXT(F5,"yyyy-mm-dd"),"','",TEXT(G5,"yyyy-mm-dd"),"',",H5,",",I5,",",L5,"),") -> (43,'SP3-OZ1/OZ2','Station de Pompage SP2-OZ1/OZ2','2002-05-20','2003-12-30',NULL,1,10),
A6: 44 | B6: OZ1/OZ2 | C6: =_xlfn.XLOOKUP(B6,'02-03-07'!B$3:B$24,'02-03-07'!A$3:A$24) -> #NAME? | D6: SP4-OZ1/OZ2 | E6: Station de Pompage SP2-OZ1/OZ2 | F6: 37848 | G6: 38433 | H6: NULL | I6: 1 | J6: Pumping Station | K6: 7 | L6: 10 | M6: =CONCATENATE("(",A6,",'",D6,"','",E6,"','",TEXT(F6,"yyyy-mm-dd"),"','",TEXT(G6,"yyyy-mm-dd"),"',",H6,",",I6,",",L6,"),") -> (44,'SP4-OZ1/OZ2','Station de Pompage SP2-OZ1/OZ2','2003-08-15','2005-03-22',NULL,1,10),
A7: 45 | B7: OZ1/OZ2 | C7: =_xlfn.XLOOKUP(B7,'02-03-07'!B$3:B$24,'02-03-07'!A$3:A$24) -> #NAME? | D7: SP5-OZ1/OZ2 | E7: Station de Pompage SP2-OZ1/OZ2 | F7: 38265 | G7: 38886 | H7: NULL | I7: 1 | J7: Pumping Station | K7: 7 | L7: 10 | M7: =CONCATENATE("(",A7,",'",D7,"','",E7,"','",TEXT(F7,"yyyy-mm-dd"),"','",TEXT(G7,"yyyy-mm-dd"),"',",H7,",",I7,",",L7,"),") -> (45,'SP5-OZ1/OZ2','Station de Pompage SP2-OZ1/OZ2','2004-10-05','2006-06-18',NULL,1,10),
A8: 46 | B8: OZ1/OZ2 | C8: =_xlfn.XLOOKUP(B8,'02-03-07'!B$3:B$24,'02-03-07'!A$3:A$24) -> #NAME? | D8: SP6-OZ1/OZ2 | E8: Station de Pompage SP2-OZ1/OZ2 | F8: 38698 | G8: 39319 | H8: NULL | I8: 1 | J8: Pumping Station | K8: 7 | L8: 10 | M8: =CONCATENATE("(",A8,",'",D8,"','",E8,"','",TEXT(F8,"yyyy-mm-dd"),"','",TEXT(G8,"yyyy-mm-dd"),"',",H8,",",I8,",",L8,"),") -> (46,'SP6-OZ1/OZ2','Station de Pompage SP2-OZ1/OZ2','2005-12-12','2007-08-25',NULL,1,10),
A9: 47 | B9: OZ1/OZ2 | C9: =_xlfn.XLOOKUP(B9,'02-03-07'!B$3:B$24,'02-03-07'!A$3:A$24) -> #NAME? | D9: PRS-OZ1/OZ2 | E9: Station de Régulation PRS-OZ1/OZ2 | F9: 38796 | G9: 39396 | H9: NULL | I9: 1 | J9: Regulator Station | K9: 9 | L9: 10 | M9: =CONCATENATE("(",A9,",'",D9,"','",E9,"','",TEXT(F9,"yyyy-mm-dd"),"','",TEXT(G9,"yyyy-mm-dd"),"',",H9,",",I9,",",L9,"),") -> (47,'PRS-OZ1/OZ2','Station de Régulation PRS-OZ1/OZ2','2006-03-20','2007-11-10',NULL,1,10),
A10: 48 | B10: OZ1/OZ2 | C10: =_xlfn.XLOOKUP(B10,'02-03-07'!B$3:B$24,'02-03-07'!A$3:A$24) -> #NAME? | D10: SP1-OZ1-D | E10: Station de Pompage SP1-OZ1-D | F10: 23743 | G10: 23743 | H10: 37986 | I10: 8 | J10: Pumping Station | K10: 7 | L10: 10 | M10: =CONCATENATE("(",A10,",'",D10,"','",E10,"','",TEXT(F10,"yyyy-mm-dd"),"','",TEXT(G10,"yyyy-mm-dd"),"',",H10,",",I10,",",L10,"),") -> (48,'SP1-OZ1-D','Station de Pompage SP1-OZ1-D','1965-01-01','1965-01-01',37986,8,10),
A11: 49 | B11: OZ1/OZ2 | C11: =_xlfn.XLOOKUP(B11,'02-03-07'!B$3:B$24,'02-03-07'!A$3:A$24) -> #NAME? | D11: SP2-OZ1-D | E11: Station de Pompage SP2-OZ1-D | F11: 23743 | G11: 23743 | H11: 37986 | I11: 8 | J11: Pumping Station | K11: 7 | L11: 10 | M11: =CONCATENATE("(",A11,",'",D11,"','",E11,"','",TEXT(F11,"yyyy-mm-dd"),"','",TEXT(G11,"yyyy-mm-dd"),"',",H11,",",I11,",",L11,"),") -> (49,'SP2-OZ1-D','Station de Pompage SP2-OZ1-D','1965-01-01','1965-01-01',37986,8,10),
A12: 50 | B12: OZ1/OZ2 | C12: =_xlfn.XLOOKUP(B12,'02-03-07'!B$3:B$24,'02-03-07'!A$3:A$24) -> #NAME? | D12: SP3-OZ1-D | E12: Station de Pompage SP2-OZ1-D | F12: 23743 | G12: 23743 | H12: 37986 | I12: 8 | J12: Pumping Station | K12: 7 | L12: 10 | M12: =CONCATENATE("(",A12,",'",D12,"','",E12,"','",TEXT(F12,"yyyy-mm-dd"),"','",TEXT(G12,"yyyy-mm-dd"),"',",H12,",",I12,",",L12,"),") -> (50,'SP3-OZ1-D','Station de Pompage SP2-OZ1-D','1965-01-01','1965-01-01',37986,8,10),
A13: 51 | B13: OZ1/OZ2 | C13: =_xlfn.XLOOKUP(B13,'02-03-07'!B$3:B$24,'02-03-07'!A$3:A$24) -> #NAME? | D13: SP4-OZ1-D | E13: Station de Pompage SP2-OZ1-D | F13: 23743 | G13: 23743 | H13: 38352 | I13: 8 | J13: Pumping Station | K13: 7 | L13: 10 | M13: =CONCATENATE("(",A13,",'",D13,"','",E13,"','",TEXT(F13,"yyyy-mm-dd"),"','",TEXT(G13,"yyyy-mm-dd"),"',",H13,",",I13,",",L13,"),") -> (51,'SP4-OZ1-D','Station de Pompage SP2-OZ1-D','1965-01-01','1965-01-01',38352,8,10),
A14: 52 | B14: OZ1/OZ2 | C14: =_xlfn.XLOOKUP(B14,'02-03-07'!B$3:B$24,'02-03-07'!A$3:A$24) -> #NAME? | D14: SP5-OZ1-D | E14: Station de Pompage SP2-OZ1-D | F14: 23743 | G14: 23743 | H14: 40178 | I14: 8 | J14: Pumping Station | K14: 7 | L14: 10 | M14: =CONCATENATE("(",A14,",'",D14,"','",E14,"','",TEXT(F14,"yyyy-mm-dd"),"','",TEXT(G14,"yyyy-mm-dd"),"',",H14,",",I14,",",L14,"),") -> (52,'SP5-OZ1-D','Station de Pompage SP2-OZ1-D','1965-01-01','1965-01-01',40178,8,10),
A15: 53 | B15: OZ1/OZ2 | C15: =_xlfn.XLOOKUP(B15,'02-03-07'!B$3:B$24,'02-03-07'!A$3:A$24) -> #NAME? | D15: SP6-OZ1-D | E15: Station de Pompage SP2-OZ1-D | F15: 23743 | G15: 23743 | H15: 38352 | I15: 8 | J15: Pumping Station | K15: 7 | L15: 10 | M15: =CONCATENATE("(",A15,",'",D15,"','",E15,"','",TEXT(F15,"yyyy-mm-dd"),"','",TEXT(G15,"yyyy-mm-dd"),"',",H15,",",I15,",",L15,"),") -> (53,'SP6-OZ1-D','Station de Pompage SP2-OZ1-D','1965-01-01','1965-01-01',38352,8,10),
A16: 54 | B16: OZ1/OZ2 | C16: =_xlfn.XLOOKUP(B16,'02-03-07'!B$3:B$24,'02-03-07'!A$3:A$24) -> #NAME? | D16: PRS-OZ1-D | E16: Station de Régulation PRS-OZ1-D | F16: 23743 | G16: 23743 | H16: 43465 | I16: 8 | J16: Regulator Station | K16: 9 | L16: 10 | M16: =CONCATENATE("(",A16,",'",D16,"','",E16,"','",TEXT(F16,"yyyy-mm-dd"),"','",TEXT(G16,"yyyy-mm-dd"),"',",H16,",",I16,",",L16,"),") -> (54,'PRS-OZ1-D','Station de Régulation PRS-OZ1-D','1965-01-01','1965-01-01',43465,8,10),
A17: 55 | B17: OK1 | C17: =_xlfn.XLOOKUP(B17,'02-03-07'!B$3:B$24,'02-03-07'!A$3:A$24) -> #NAME? | D17: SP1-OK1 | E17: Station de Pompage SP1-OK1 | F17: 37057 | G17: 37672 | H17: NULL | I17: 1 | J17: Pumping Station | K17: 7 | L17: 10 | M17: =CONCATENATE("(",A17,",'",D17,"','",E17,"','",TEXT(F17,"yyyy-mm-dd"),"','",TEXT(G17,"yyyy-mm-dd"),"',",H17,",",I17,",",L17,"),") -> (55,'SP1-OK1','Station de Pompage SP1-OK1','2001-06-15','2003-02-20',NULL,1,10),
A18: 56 | B18: OK1 | C18: =_xlfn.XLOOKUP(B18,'02-03-07'!B$3:B$24,'02-03-07'!A$3:A$24) -> #NAME? | D18: R-SP1-OK1 | E18: Station de Pompage RSP1-OK1 | F18: 40278 | G18: 40923 | H18: NULL | I18: 1 | J18: Pumping Station | K18: 7 | L18: 10 | M18: =CONCATENATE("(",A18,",'",D18,"','",E18,"','",TEXT(F18,"yyyy-mm-dd"),"','",TEXT(G18,"yyyy-mm-dd"),"',",H18,",",I18,",",L18,"),") -> (56,'R-SP1-OK1','Station de Pompage RSP1-OK1','2010-04-10','2012-01-15',NULL,1,10),
A19: 57 | B19: OK1 | C19: =_xlfn.XLOOKUP(B19,'02-03-07'!B$3:B$24,'02-03-07'!A$3:A$24) -> #NAME? | D19: SP2-OK1 | E19: Station de Pompage SP2-OK1 | F19: 37490 | G19: 38137 | H19: NULL | I19: 1 | J19: Pumping Station | K19: 7 | L19: 10 | M19: =CONCATENATE("(",A19,",'",D19,"','",E19,"','",TEXT(F19,"yyyy-mm-dd"),"','",TEXT(G19,"yyyy-mm-dd"),"',",H19,",",I19,",",L19,"),") -> (57,'SP2-OK1','Station de Pompage SP2-OK1','2002-08-22','2004-05-30',NULL,1,10),
A20: 58 | B20: OK1 | C20: =_xlfn.XLOOKUP(B20,'02-03-07'!B$3:B$24,'02-03-07'!A$3:A$24) -> #NAME? | D20: SP3-OK1 | E20: Station de Pompage SP3-OK1 | F20: 37930 | G20: 38551 | H20: NULL | I20: 1 | J20: Pumping Station | K20: 7 | L20: 10 | M20: =CONCATENATE("(",A20,",'",D20,"','",E20,"','",TEXT(F20,"yyyy-mm-dd"),"','",TEXT(G20,"yyyy-mm-dd"),"',",H20,",",I20,",",L20,"),") -> (58,'SP3-OK1','Station de Pompage SP3-OK1','2003-11-05','2005-07-18',NULL,1,10),
A21: 59 | B21: OK1 | C21: =_xlfn.XLOOKUP(B21,'02-03-07'!B$3:B$24,'02-03-07'!A$3:A$24) -> #NAME? | D21: SP4-OK1 | E21: Station de Pompage SP4-OK1 | F21: 38125 | G21: 38739 | H21: NULL | I21: 1 | J21: Pumping Station | K21: 7 | L21: 10 | M21: =CONCATENATE("(",A21,",'",D21,"','",E21,"','",TEXT(F21,"yyyy-mm-dd"),"','",TEXT(G21,"yyyy-mm-dd"),"',",H21,",",I21,",",L21,"),") -> (59,'SP4-OK1','Station de Pompage SP4-OK1','2004-05-18','2006-01-22',NULL,1,10),
A22: 60 | B22: OB1/OG1 | C22: =_xlfn.XLOOKUP(B22,'02-03-07'!B$3:B$24,'02-03-07'!A$3:A$24) -> #NAME? | D22: SP1-OB1 | E22: Station de Pompage SP1-OB1 | F22: 37327 | G22: 37950 | H22: NULL | I22: 1 | J22: Pumping Station | K22: 7 | L22: 10 | M22: =CONCATENATE("(",A22,",'",D22,"','",E22,"','",TEXT(F22,"yyyy-mm-dd"),"','",TEXT(G22,"yyyy-mm-dd"),"',",H22,",",I22,",",L22,"),") -> (60,'SP1-OB1','Station de Pompage SP1-OB1','2002-03-12','2003-11-25',NULL,1,10),
A23: 61 | B23: OB1/OG1 | C23: =_xlfn.XLOOKUP(B23,'02-03-07'!B$3:B$24,'02-03-07'!A$3:A$24) -> #NAME? | D23: SP1-BIS-OB1 | E23: Station de Pompage SP1-BIS-OB1 | F23: 39649 | G23: 40283 | H23: NULL | I23: 1 | J23: Pumping Station | K23: 7 | L23: 10 | M23: =CONCATENATE("(",A23,",'",D23,"','",E23,"','",TEXT(F23,"yyyy-mm-dd"),"','",TEXT(G23,"yyyy-mm-dd"),"',",H23,",",I23,",",L23,"),") -> (61,'SP1-BIS-OB1','Station de Pompage SP1-BIS-OB1','2008-07-20','2010-04-15',NULL,1,10),
A24: 62 | B24: OB1/OG1 | C24: =_xlfn.XLOOKUP(B24,'02-03-07'!B$3:B$24,'02-03-07'!A$3:A$24) -> #NAME? | D24: SP2-OB1 | E24: Station de Pompage SP2-OB1 | F24: 37874 | G24: 38521 | H24: NULL | I24: 1 | J24: Pumping Station | K24: 7 | L24: 10 | M24: =CONCATENATE("(",A24,",'",D24,"','",E24,"','",TEXT(F24,"yyyy-mm-dd"),"','",TEXT(G24,"yyyy-mm-dd"),"',",H24,",",I24,",",L24,"),") -> (62,'SP2-OB1','Station de Pompage SP2-OB1','2003-09-10','2005-06-18',NULL,1,10),
A25: 63 | B25: OB1/OG1 | C25: =_xlfn.XLOOKUP(B25,'02-03-07'!B$3:B$24,'02-03-07'!A$3:A$24) -> #NAME? | D25: SP3-OB1 | E25: Station de Pompage SP3-OB1 | F25: 38326 | G25: 38951 | H25: NULL | I25: 1 | J25: Pumping Station | K25: 7 | L25: 10 | M25: =CONCATENATE("(",A25,",'",D25,"','",E25,"','",TEXT(F25,"yyyy-mm-dd"),"','",TEXT(G25,"yyyy-mm-dd"),"',",H25,",",I25,",",L25,"),") -> (63,'SP3-OB1','Station de Pompage SP3-OB1','2004-12-05','2006-08-22',NULL,1,10),
A26: 64 | B26: OB1/OG1 | C26: =_xlfn.XLOOKUP(B26,'02-03-07'!B$3:B$24,'02-03-07'!A$3:A$24) -> #NAME? | D26: SP1-OG1 | E26: Station de Pompage SP1-OG1 | F26: 39190 | G26: 39843 | H26: NULL | I26: 1 | J26: Pumping Station | K26: 7 | L26: 10 | M26: =CONCATENATE("(",A26,",'",D26,"','",E26,"','",TEXT(F26,"yyyy-mm-dd"),"','",TEXT(G26,"yyyy-mm-dd"),"',",H26,",",I26,",",L26,"),") -> (64,'SP1-OG1','Station de Pompage SP1-OG1','2007-04-18','2009-01-30',NULL,1,10),
A27: 65 | B27: OB1/OG1 | C27: =_xlfn.XLOOKUP(B27,'02-03-07'!B$3:B$24,'02-03-07'!A$3:A$24) -> #NAME? | D27: SP1-OB1-D | E27: =CONCATENATE("Station de Pompage ",D27) -> Station de Pompage SP1-OB1-D | F27: 21916 | G27: 21916 | H27: 43830 | I27: 8 | J27: Pumping Station | K27: 7 | L27: 10 | M27: =CONCATENATE("(",A27,",'",D27,"','",E27,"','",TEXT(F27,"yyyy-mm-dd"),"','",TEXT(G27,"yyyy-mm-dd"),"','",TEXT(H27,"yyyy-mm-dd"),"',",I27,",",L27,"),") -> (65,'SP1-OB1-D','Station de Pompage SP1-OB1-D','1960-01-01','1960-01-01','2019-12-31',8,10),
A28: 66 | B28: OB1/OG1 | C28: =_xlfn.XLOOKUP(B28,'02-03-07'!B$3:B$24,'02-03-07'!A$3:A$24) -> #NAME? | D28: SP1-BIS-OB1-D | E28: =CONCATENATE("Station de Pompage ",D28) -> Station de Pompage SP1-BIS-OB1-D | F28: 21916 | G28: 21916 | H28: 39447 | I28: 8 | J28: Pumping Station | K28: 7 | L28: 10 | M28: =CONCATENATE("(",A28,",'",D28,"','",E28,"','",TEXT(F28,"yyyy-mm-dd"),"','",TEXT(G28,"yyyy-mm-dd"),"','",TEXT(H28,"yyyy-mm-dd"),"',",I28,",",L28,"),") -> (66,'SP1-BIS-OB1-D','Station de Pompage SP1-BIS-OB1-D','1960-01-01','1960-01-01','2007-12-31',8,10),
A29: 67 | B29: OB1/OG1 | C29: =_xlfn.XLOOKUP(B29,'02-03-07'!B$3:B$24,'02-03-07'!A$3:A$24) -> #NAME? | D29: SP2-OB1-D | E29: =CONCATENATE("Station de Pompage ",D29) -> Station de Pompage SP2-OB1-D | F29: 21916 | G29: 21916 | H29: 39813 | I29: 8 | J29: Pumping Station | K29: 7 | L29: 10 | M29: =CONCATENATE("(",A29,",'",D29,"','",E29,"','",TEXT(F29,"yyyy-mm-dd"),"','",TEXT(G29,"yyyy-mm-dd"),"','",TEXT(H29,"yyyy-mm-dd"),"',",I29,",",L29,"),") -> (67,'SP2-OB1-D','Station de Pompage SP2-OB1-D','1960-01-01','1960-01-01','2008-12-31',8,10),
A30: 68 | B30: OB1/OG1 | C30: =_xlfn.XLOOKUP(B30,'02-03-07'!B$3:B$24,'02-03-07'!A$3:A$24) -> #NAME? | D30: SP3-OB1-D | E30: =CONCATENATE("Station de Pompage ",D30) -> Station de Pompage SP3-OB1-D | F30: 21551 | G30: 21551 | H30: 39813 | I30: 8 | J30: Pumping Station | K30: 7 | L30: 10 | M30: =CONCATENATE("(",A30,",'",D30,"','",E30,"','",TEXT(F30,"yyyy-mm-dd"),"','",TEXT(G30,"yyyy-mm-dd"),"','",TEXT(H30,"yyyy-mm-dd"),"',",I30,",",L30,"),") -> (68,'SP3-OB1-D','Station de Pompage SP3-OB1-D','1959-01-01','1959-01-01','2008-12-31',8,10),
A31: 69 | B31: OB1/OG1 | C31: =_xlfn.XLOOKUP(B31,'02-03-07'!B$3:B$24,'02-03-07'!A$3:A$24) -> #NAME? | D31: SPA-OB1-D | E31: =CONCATENATE("Station de Pompage ",D31) -> Station de Pompage SPA-OB1-D | F31: 25569 | G31: 25569 | H31: 36160 | I31: 8 | J31: Pumping Station | K31: 7 | L31: 10 | M31: =CONCATENATE("(",A31,",'",D31,"','",E31,"','",TEXT(F31,"yyyy-mm-dd"),"','",TEXT(G31,"yyyy-mm-dd"),"','",TEXT(H31,"yyyy-mm-dd"),"',",I31,",",L31,"),") -> (69,'SPA-OB1-D','Station de Pompage SPA-OB1-D','1970-01-01','1970-01-01','1998-12-31',8,10),
A32: 70 | B32: OB1/OG1 | C32: =_xlfn.XLOOKUP(B32,'02-03-07'!B$3:B$24,'02-03-07'!A$3:A$24) -> #NAME? | D32: SPB-OB1-D | E32: =CONCATENATE("Station de Pompage ",D32) -> Station de Pompage SPB-OB1-D | F32: 25569 | G32: 25569 | H32: 39447 | I32: 8 | J32: Pumping Station | K32: 7 | L32: 10 | M32: =CONCATENATE("(",A32,",'",D32,"','",E32,"','",TEXT(F32,"yyyy-mm-dd"),"','",TEXT(G32,"yyyy-mm-dd"),"','",TEXT(H32,"yyyy-mm-dd"),"',",I32,",",L32,"),") -> (70,'SPB-OB1-D','Station de Pompage SPB-OB1-D','1970-01-01','1970-01-01','2007-12-31',8,10),
A33: 71 | B33: OB1/OG1 | C33: =_xlfn.XLOOKUP(B33,'02-03-07'!B$3:B$24,'02-03-07'!A$3:A$24) -> #NAME? | D33: SPC-OB1-D | E33: =CONCATENATE("Station de Pompage ",D33) -> Station de Pompage SPC-OB1-D | F33: 25569 | G33: 25569 | H33: 37256 | I33: 8 | J33: Pumping Station | K33: 7 | L33: 10 | M33: =CONCATENATE("(",A33,",'",D33,"','",E33,"','",TEXT(F33,"yyyy-mm-dd"),"','",TEXT(G33,"yyyy-mm-dd"),"','",TEXT(H33,"yyyy-mm-dd"),"',",I33,",",L33,"),") -> (71,'SPC-OB1-D','Station de Pompage SPC-OB1-D','1970-01-01','1970-01-01','2001-12-31',8,10),
A34: 72 | B34: OB1/OG1 | C34: =_xlfn.XLOOKUP(B34,'02-03-07'!B$3:B$24,'02-03-07'!A$3:A$24) -> #NAME? | D34: SPD-OB1-D | E34: =CONCATENATE("Station de Pompage ",D34) -> Station de Pompage SPD-OB1-D | F34: 25569 | G34: 25569 | H34: 34699 | I34: 8 | J34: Pumping Station | K34: 7 | L34: 10 | M34: =CONCATENATE("(",A34,",'",D34,"','",E34,"','",TEXT(F34,"yyyy-mm-dd"),"','",TEXT(G34,"yyyy-mm-dd"),"','",TEXT(H34,"yyyy-mm-dd"),"',",I34,",",L34,"),") -> (72,'SPD-OB1-D','Station de Pompage SPD-OB1-D','1970-01-01','1970-01-01','1994-12-31',8,10),
A35: 73 | B35: OB1/OG1 | C35: =_xlfn.XLOOKUP(B35,'02-03-07'!B$3:B$24,'02-03-07'!A$3:A$24) -> #NAME? | D35: SP-OG1-D | E35: =CONCATENATE("Station de Pompage ",D35) -> Station de Pompage SP-OG1-D | F35: 25934 | G35: 25934 | H35: 38717 | I35: 8 | J35: Pumping Station | K35: 7 | L35: 10 | M35: =CONCATENATE("(",A35,",'",D35,"','",E35,"','",TEXT(F35,"yyyy-mm-dd"),"','",TEXT(G35,"yyyy-mm-dd"),"','",TEXT(H35,"yyyy-mm-dd"),"',",I35,",",L35,"),") -> (73,'SP-OG1-D','Station de Pompage SP-OG1-D','1971-01-01','1971-01-01','2005-12-31',8,10),
A36: 74 | B36: OT1 | C36: =_xlfn.XLOOKUP(B36,'02-03-07'!B$3:B$24,'02-03-07'!A$3:A$24) -> #NAME? | D36: SP1-OT1 | E36: =CONCATENATE("Station de Pompage ",D36) -> Station de Pompage SP1-OT1 | F36: 21916 | G36: 21916 | H36: NULL | I36: 1 | J36: Pumping Station | K36: 7 | L36: 10 | M36: =CONCATENATE("(",A36,",'",D36,"','",E36,"','",TEXT(F36,"yyyy-mm-dd"),"','",TEXT(G36,"yyyy-mm-dd"),"',",H36,",",I36,",",L36,"),") -> (74,'SP1-OT1','Station de Pompage SP1-OT1','1960-01-01','1960-01-01',NULL,1,10),
A37: 75 | B37: OT1 | C37: =_xlfn.XLOOKUP(B37,'02-03-07'!B$3:B$24,'02-03-07'!A$3:A$24) -> #NAME? | D37: SP2-OT1 | E37: =CONCATENATE("Station de Pompage ",D37) -> Station de Pompage SP2-OT1 | F37: 21916 | G37: 21916 | H37: NULL | I37: 1 | J37: Pumping Station | K37: 7 | L37: 10 | M37: =CONCATENATE("(",A37,",'",D37,"','",E37,"','",TEXT(F37,"yyyy-mm-dd"),"','",TEXT(G37,"yyyy-mm-dd"),"',",H37,",",I37,",",L37,"),") -> (75,'SP2-OT1','Station de Pompage SP2-OT1','1960-01-01','1960-01-01',NULL,1,10),
A38: 76 | B38: OH1 | C38: =_xlfn.XLOOKUP(B38,'02-03-07'!B$3:B$24,'02-03-07'!A$3:A$24) -> #NAME? | D38: OPS1-OH1 | E38: =CONCATENATE("Station de Pompage ",D38) -> Station de Pompage OPS1-OH1 | F38: 27395 | G38: 27395 | H38: NULL | I38: 1 | J38: Pumping Station | K38: 7 | L38: 10 | M38: =CONCATENATE("(",A38,",'",D38,"','",E38,"','",TEXT(F38,"yyyy-mm-dd"),"','",TEXT(G38,"yyyy-mm-dd"),"',",H38,",",I38,",",L38,"),") -> (76,'OPS1-OH1','Station de Pompage OPS1-OH1','1975-01-01','1975-01-01',NULL,1,10),
